Workbook

Sheet Sheet1
A1: ნაკვეთის კოდი | B1: ნაკვეთის ფართობი (მ2) | C1: მიწის 1მ2 ფასი | D1: მიწის ღირებულება $ | E1: სახლის სტილი | F1: სახლის ფართი (მ2) | G1: ობიექტის რეალიზაციის ფასი 1 მ2 $ | H1: საინვესტიცო ღირებულება | I1: ბეი - რეზერვი $ | J1: პირველი შენატანი 10% | K1: პოსტ-ჰენდოვერი (20%) | L1: ყოველთვიური (36 თვე) | M1: სააქციო შეთავაზება 8% გარანტირებული უკუგება 2 წელი | N1: დღიური ქირის ფასი ($) | O1: პასიური წლიური 45% დათვირთვით შემოსავალი | P1: პესიმისტური Rental ROI % | Q1: პესიმისტური უკუგება (წელი)
A2: LA-1 | B2: 702.4 | C2: 120 | D2: =C2*B2 -> 84288 | E2: Modern Flat-Roof | F2: 145 | G2: 2000 | H2: =G2*F2+D2 -> 374288 | I2: 5000 | J2: =(H2*0.1)-I2 -> 32428.8 | K2: =H2*0.2 -> 74857.6 | L2: =(H2-I2-J2-K2)/36 -> 7277.8222 | M2: =(H2*0.08)/12 -> 2495.2533 | N2: 400 | O2: =(N2*365*0.45)*0.6 -> 39420 | P2: =(O2/H2)*100 -> 10.531997 | Q2: =H2/O2 -> 9.4948757
A3: LA-3 | B3: 683.2 | C3: 120 | D3: =C3*B3 -> 81984 | E3: Modern Flat-Roof | F3: 145 | G3: 2000 | H3: =G3*F3+D3 -> 371984 | I3: 5000 | J3: =(H3*0.1)-I3 -> 32198.4 | K3: =H3*0.2 -> 74396.8 | L3: =(H3-I3-J3-K3)/36 -> 7233.0222 | M3: =(H3*0.08)/12 -> 2479.8933 | N3: 400 | O3: =(N3*365*0.45)*0.6 -> 39420 | P3: =(O3/H3)*100 -> 10.59723 | Q3: =H3/O3 -> 9.4364282
A4: LA-5 | B4: 652.7 | C4: 120 | D4: =C4*B4 -> 78324 | E4: Modern Flat-Roof | F4: 145 | G4: 2000 | H4: =G4*F4+D4 -> 368324 | I4: 5000 | J4: =(H4*0.1)-I4 -> 31832.4 | K4: =H4*0.2 -> 73664.8 | L4: =(H4-I4-J4-K4)/36 -> 7161.8556 | M4: =(H4*0.08)/12 -> 2455.4933 | N4: 400 | O4: =(N4*365*0.45)*0.6 -> 39420 | P4: =(O4/H4)*100 -> 10.702534 | Q4: =H4/O4 -> 9.3435819
A5: LA-7 | B5: 558.9 | C5: 120 | D5: =C5*B5 -> 67068 | E5: Barnhouse | F5: 115 | G5: 2000 | H5: =G5*F5+D5 -> 297068 | I5: 5000 | J5: =(H5*0.1)-I5 -> 24706.8 | K5: =H5*0.2 -> 59413.6 | L5: =(H5-I5-J5-K5)/36 -> 5776.3222 | N5: 300 | O5: =(N5*365*0.45)*0.6 -> 29565 | P5: =(O5/H5)*100 -> 9.9522668 | Q5: =H5/O5 -> 10.047962
A6: LA-9 | B6: 561.5 | C6: 120 | D6: =C6*B6 -> 67380 | E6: Barnhouse | F6: 115 | G6: 2000 | H6: =G6*F6+D6 -> 297380 | I6: 5000 | J6: =(H6*0.1)-I6 -> 24738 | K6: =H6*0.2 -> 59476 | L6: =(H6-I6-J6-K6)/36 -> 5782.3889 | N6: 300 | O6: =(N6*365*0.45)*0.6 -> 29565 | P6: =(O6/H6)*100 -> 9.9418253 | Q6: =H6/O6 -> 10.058515
A7: LA-11 | B7: 740.3 | C7: 120 | D7: =C7*B7 -> 88836 | E7: Modern Flat-Roof | F7: 145 | G7: 2000 | H7: =G7*F7+D7 -> 378836 | I7: 5000 | J7: =(H7*0.1)-I7 -> 32883.6 | K7: =H7*0.2 -> 75767.2 | L7: =(H7-I7-J7-K7)/36 -> 7366.2556 | M7: =(H7*0.08)/12 -> 2525.5733 | N7: 400 | O7: =(N7*365*0.45)*0.6 -> 39420 | P7: =(O7/H7)*100 -> 10.405558 | Q7: =H7/O7 -> 9.6102486
A8: LA-13 | B8: 953.6 | C8: 120 | D8: =C8*B8 -> 114432 | E8: Modern Flat-Roof | F8: 145 | G8: 2000 | H8: =G8*F8+D8 -> 404432 | I8: 5000 | J8: =(H8*0.1)-I8 -> 35443.2 | K8: =H8*0.2 -> 80886.4 | L8: =(H8-I8-J8-K8)/36 -> 7863.9556 | M8: =(H8*0.08)/12 -> 2696.2133 | N8: 400 | O8: =(N8*365*0.45)*0.6 -> 39420 | P8: =(O8/H8)*100 -> 9.7470032 | Q8: =H8/O8 -> 10.259564
A9: LA-15 | B9: 1084.1 | C9: 120 | D9: =C9*B9 -> 130092 | E9: Modern Flat-Roof | F9: 145 | G9: 2000 | H9: =G9*F9+D9 -> 420092 | I9: 5000 | J9: =(H9*0.1)-I9 -> 37009.2 | K9: =H9*0.2 -> 84018.4 | L9: =(H9-I9-J9-K9)/36 -> 8168.4556 | M9: =(H9*0.08)/12 -> 2800.6133 | N9: 400 | O9: =(N9*365*0.45)*0.6 -> 39420 | P9: =(O9/H9)*100 -> 9.3836588 | Q9: =H9/O9 -> 10.656824
A10: LA-17 | B10: 503.7 | C10: 120 | D10: =C10*B10 -> 60444 | E10: Barnhouse | F10: 115 | G10: 2000 | H10: =G10*F10+D10 -> 290444 | I10: 5000 | J10: =(H10*0.1)-I10 -> 24044.4 | K10: =H10*0.2 -> 58088.8 | L10: =(H10-I10-J10-K10)/36 -> 5647.5222 | N10: 300 | O10: =(N10*365*0.45)*0.6 -> 29565 | P10: =(O10/H10)*100 -> 10.179243 | Q10: =H10/O10 -> 9.8239134
A11: LA-19 | B11: 413.4 | C11: 120 | D11: =C11*B11 -> 49608 | E11: Barnhouse | F11: 85 | G11: 2000 | H11: =G11*F11+D11 -> 219608 | I11: 5000 | J11: =(H11*0.1)-I11 -> 16960.8 | K11: =H11*0.2 -> 43921.6 | L11: =(H11-I11-J11-K11)/36 -> 4270.1556 | N11: 250 | O11: =(N11*365*0.45)*0.6 -> 24637.5 | P11: =(O11/H11)*100 -> 11.218854 | Q11: =H11/O11 -> 8.9135667
A12: LA-21 | B12: 393 | C12: 120 | D12: =C12*B12 -> 47160 | E12: Barnhouse | F12: 85 | G12: 2000 | H12: =G12*F12+D12 -> 217160 | I12: 5000 | J12: =(H12*0.1)-I12 -> 16716 | K12: =H12*0.2 -> 43432 | L12: =(H12-I12-J12-K12)/36 -> 4222.5556 | N12: 250 | O12: =(N12*365*0.45)*0.6 -> 24637.5 | P12: =(O12/H12)*100 -> 11.345321 | Q12: =H12/O12 -> 8.814206
A13: LA-23 | B13: 404.7 | C13: 120 | D13: =C13*B13 -> 48564 | E13: Barnhouse | F13: 85 | G13: 2000 | H13: =G13*F13+D13 -> 218564 | I13: 5000 | J13: =(H13*0.1)-I13 -> 16856.4 | K13: =H13*0.2 -> 43712.8 | L13: =(H13-I13-J13-K13)/36 -> 4249.8556 | N13: 250 | O13: =(N13*365*0.45)*0.6 -> 24637.5 | P13: =(O13/H13)*100 -> 11.272442 | Q13: =H13/O13 -> 8.8711923
A14: LA-25 | B14: 485.3 | C14: 120 | D14: =C14*B14 -> 58236 | E14: Barnhouse | F14: 115 | G14: 2000 | H14: =G14*F14+D14 -> 288236 | I14: 5000 | J14: =(H14*0.1)-I14 -> 23823.6 | K14: =H14*0.2 -> 57647.2 | L14: =(H14-I14-J14-K14)/36 -> 5604.5889 | N14: 300 | O14: =(N14*365*0.45)*0.6 -> 29565 | P14: =(O14/H14)*100 -> 10.25722 | Q14: =H14/O14 -> 9.7492305
A15: LA-27 | B15: 479.7 | C15: 120 | D15: =C15*B15 -> 57564 | E15: Barnhouse | F15: 115 | G15: 2000 | H15: =G15*F15+D15 -> 287564 | I15: 5000 | J15: =(H15*0.1)-I15 -> 23756.4 | K15: =H15*0.2 -> 57512.8 | L15: =(H15-I15-J15-K15)/36 -> 5591.5222 | N15: 300 | O15: =(N15*365*0.45)*0.6 -> 29565 | P15: =(O15/H15)*100 -> 10.28119 | Q15: =H15/O15 -> 9.7265009
A16: LA-29 | B16: 652.9 | C16: 120 | D16: =C16*B16 -> 78348 | E16: Modern Flat-Roof | F16: 145 | G16: 2000 | H16: =G16*F16+D16 -> 368348 | I16: 5000 | J16: =(H16*0.1)-I16 -> 31834.8 | K16: =H16*0.2 -> 73669.6 | L16: =(H16-I16-J16-K16)/36 -> 7162.3222 | M16: =(H16*0.08)/12 -> 2455.6533 | N16: 400 | O16: =(N16*365*0.45)*0.6 -> 39420 | P16: =(O16/H16)*100 -> 10.701836 | Q16: =H16/O16 -> 9.3441908
A17: LA-31 | B17: 513.9 | C17: 120 | D17: =C17*B17 -> 61668 | E17: Barnhouse | F17: 115 | G17: 2000 | H17: =G17*F17+D17 -> 291668 | I17: 5000 | J17: =(H17*0.1)-I17 -> 24166.8 | K17: =H17*0.2 -> 58333.6 | L17: =(H17-I17-J17-K17)/36 -> 5671.3222 | N17: 300 | O17: =(N17*365*0.45)*0.6 -> 29565 | P17: =(O17/H17)*100 -> 10.136525 | Q17: =H17/O17 -> 9.8653137
A18: LA-33 | B18: 451.8 | C18: 120 | D18: =C18*B18 -> 54216 | E18: Barnhouse | F18: 115 | G18: 2000 | H18: =G18*F18+D18 -> 284216 | I18: 5000 | J18: =(H18*0.1)-I18 -> 23421.6 | K18: =H18*0.2 -> 56843.2 | L18: =(H18-I18-J18-K18)/36 -> 5526.4222 | N18: 300 | O18: =(N18*365*0.45)*0.6 -> 29565 | P18: =(O18/H18)*100 -> 10.4023 | Q18: =H18/O18 -> 9.6132589
A19: LA-35 | B19: 509 | C19: 120 | D19: =C19*B19 -> 61080 | E19: Barnhouse | F19: 115 | G19: 2000 | H19: =G19*F19+D19 -> 291080 | I19: 5000 | J19: =(H19*0.1)-I19 -> 24108 | K19: =H19*0.2 -> 58216 | L19: =(H19-I19-J19-K19)/36 -> 5659.8889 | N19: 300 | O19: =(N19*365*0.45)*0.6 -> 29565 | P19: =(O19/H19)*100 -> 10.157002 | Q19: =H19/O19 -> 9.8454253
A20: LA-37 | B20: 464.4 | C20: 120 | D20: =C20*B20 -> 55728 | E20: Barnhouse | F20: 115 | G20: 2000 | H20: =G20*F20+D20 -> 285728 | I20: 5000 | J20: =(H20*0.1)-I20 -> 23572.8 | K20: =H20*0.2 -> 57145.6 | L20: =(H20-I20-J20-K20)/36 -> 5555.8222 | N20: 300 | O20: =(N20*365*0.45)*0.6 -> 29565 | P20: =(O20/H20)*100 -> 10.347253 | Q20: =H20/O20 -> 9.6644005
A21: LA-39 | B21: 425.4 | C21: 120 | D21: =C21*B21 -> 51048 | E21: Barnhouse | F21: 85 | G21: 2000 | H21: =G21*F21+D21 -> 221048 | I21: 5000 | J21: =(H21*0.1)-I21 -> 17104.8 | K21: =H21*0.2 -> 44209.6 | L21: =(H21-I21-J21-K21)/36 -> 4298.1556 | N21: 250 | O21: =(N21*365*0.45)*0.6 -> 24637.5 | P21: =(O21/H21)*100 -> 11.145769 | Q21: =H21/O21 -> 8.9720142
A22: LA-41 | B22: 309 | C22: 120 | D22: =C22*B22 -> 37080 | E22: A-Frame | F22: 85 | G22: 2000 | H22: =G22*F22+D22 -> 207080 | I22: 5000 | J22: =(H22*0.1)-I22 -> 15708 | K22: =H22*0.2 -> 41416 | L22: =(H22-I22-J22-K22)/36 -> 4026.5556 | N22: 200 | O22: =(N22*365*0.45)*0.6 -> 19710 | P22: =(O22/H22)*100 -> 9.5180607 | Q22: =H22/O22 -> 10.506342
A23: LA-43 | B23: 470.5 | C23: 120 | D23: =C23*B23 -> 56460 | E23: Barnhouse | F23: 115 | G23: 2000 | H23: =G23*F23+D23 -> 286460 | I23: 5000 | J23: =(H23*0.1)-I23 -> 23646 | K23: =H23*0.2 -> 57292 | L23: =(H23-I23-J23-K23)/36 -> 5570.0556 | N23: 300 | O23: =(N23*365*0.45)*0.6 -> 29565 | P23: =(O23/H23)*100 -> 10.320813 | Q23: =H23/O23 -> 9.6891595
A24: LA-45 | B24: 628.6 | C24: 120 | D24: =C24*B24 -> 75432 | E24: Modern Flat-Roof | F24: 145 | G24: 2000 | H24: =G24*F24+D24 -> 365432 | I24: 5000 | J24: =(H24*0.1)-I24 -> 31543.2 | K24: =H24*0.2 -> 73086.4 | L24: =(H24-I24-J24-K24)/36 -> 7105.6222 | M24: =(H24*0.08)/12 -> 2436.2133 | N24: 300 | O24: =(N24*365*0.45)*0.6 -> 29565 | P24: =(O24/H24)*100 -> 8.0904245 | Q24: =H24/O24 -> 12.360291
A25: LA-47 | B25: 652.1 | C25: 120 | D25: =C25*B25 -> 78252 | E25: Modern Flat-Roof | F25: 145 | G25: 2000 | H25: =G25*F25+D25 -> 368252 | I25: 5000 | J25: =(H25*0.1)-I25 -> 31825.2 | K25: =H25*0.2 -> 73650.4 | L25: =(H25-I25-J25-K25)/36 -> 7160.4556 | M25: =(H25*0.08)/12 -> 2455.0133 | N25: 400 | O25: =(N25*365*0.45)*0.6 -> 39420 | P25: =(O25/H25)*100 -> 10.704626 | Q25: =H25/O25 -> 9.3417555
A26: LA-49 | B26: 584.2 | C26: 120 | D26: =C26*B26 -> 70104 | E26: Barnhouse | F26: 115 | G26: 2000 | H26: =G26*F26+D26 -> 300104 | I26: 5000 | J26: =(H26*0.1)-I26 -> 25010.4 | K26: =H26*0.2 -> 60020.8 | L26: =(H26-I26-J26-K26)/36 -> 5835.3556 | N26: 300 | O26: =(N26*365*0.45)*0.6 -> 29565 | P26: =(O26/H26)*100 -> 9.8515848 | Q26: =H26/O26 -> 10.150651
A27: LA-51 | B27: 443.3 | C27: 120 | D27: =C27*B27 -> 53196 | E27: Barnhouse | F27: 85 | G27: 2000 | H27: =G27*F27+D27 -> 223196 | I27: 5000 | J27: =(H27*0.1)-I27 -> 17319.6 | K27: =H27*0.2 -> 44639.2 | L27: =(H27-I27-J27-K27)/36 -> 4339.9222 | N27: 250 | O27: =(N27*365*0.45)*0.6 -> 24637.5 | P27: =(O27/H27)*100 -> 11.038504 | Q27: =H27/O27 -> 9.0591984
A28: LA-53 | B28: 348.6 | C28: 120 | D28: =C28*B28 -> 41832 | E28: A-Frame | F28: 85 | G28: 2000 | H28: =G28*F28+D28 -> 211832 | I28: 5000 | J28: =(H28*0.1)-I28 -> 16183.2 | K28: =H28*0.2 -> 42366.4 | L28: =(H28-I28-J28-K28)/36 -> 4118.9556 | N28: 200 | O28: =(N28*365*0.45)*0.6 -> 19710 | P28: =(O28/H28)*100 -> 9.3045432 | Q28: =H28/O28 -> 10.747438
A29: LA-55 | B29: 298 | C29: 120 | D29: =C29*B29 -> 35760 | E29: A-Frame | F29: 85 | G29: 2000 | H29: =G29*F29+D29 -> 205760 | I29: 5000 | J29: =(H29*0.1)-I29 -> 15576 | K29: =H29*0.2 -> 41152 | L29: =(H29-I29-J29-K29)/36 -> 4000.8889 | N29: 200 | O29: =(N29*365*0.45)*0.6 -> 19710 | P29: =(O29/H29)*100 -> 9.5791213 | Q29: =H29/O29 -> 10.439371
A30: LA-57 | B30: 366 | C30: 120 | D30: =C30*B30 -> 43920 | E30: Barnhouse | F30: 85 | G30: 2000 | H30: =G30*F30+D30 -> 213920 | I30: 5000 | J30: =(H30*0.1)-I30 -> 16392 | K30: =H30*0.2 -> 42784 | L30: =(H30-I30-J30-K30)/36 -> 4159.5556 | N30: 250 | O30: =(N30*365*0.45)*0.6 -> 24637.5 | P30: =(O30/H30)*100 -> 11.517156 | Q30: =H30/O30 -> 8.6826991
A31: LA-59 | B31: 369.6 | C31: 120 | D31: =C31*B31 -> 44352 | E31: Barnhouse | F31: 85 | G31: 2000 | H31: =G31*F31+D31 -> 214352 | I31: 5000 | J31: =(H31*0.1)-I31 -> 16435.2 | K31: =H31*0.2 -> 42870.4 | L31: =(H31-I31-J31-K31)/36 -> 4167.9556 | N31: 250 | O31: =(N31*365*0.45)*0.6 -> 24637.5 | P31: =(O31/H31)*100 -> 11.493945 | Q31: =H31/O31 -> 8.7002334
A32: LA-61 | B32: 385.3 | C32: 120 | D32: =C32*B32 -> 46236 | E32: Barnhouse | F32: 85 | G32: 2000 | H32: =G32*F32+D32 -> 216236 | I32: 5000 | J32: =(H32*0.1)-I32 -> 16623.6 | K32: =H32*0.2 -> 43247.2 | L32: =(H32-I32-J32-K32)/36 -> 4204.5889 | N32: 250 | O32: =(N32*365*0.45)*0.6 -> 24637.5 | P32: =(O32/H32)*100 -> 11.393801 | Q32: =H32/O32 -> 8.7767022
A33: LA-63 | B33: 381.8 | C33: 120 | D33: =C33*B33 -> 45816 | E33: Barnhouse | F33: 85 | G33: 2000 | H33: =G33*F33+D33 -> 215816 | I33: 5000 | J33: =(H33*0.1)-I33 -> 16581.6 | K33: =H33*0.2 -> 43163.2 | L33: =(H33-I33-J33-K33)/36 -> 4196.4222 | N33: 250 | O33: =(N33*365*0.45)*0.6 -> 24637.5 | P33: =(O33/H33)*100 -> 11.415975 | Q33: =H33/O33 -> 8.759655
A34: LA-65 | B34: 336.7 | C34: 120 | D34: =C34*B34 -> 40404 | E34: A-Frame | F34: 85 | G34: 2000 | H34: =G34*F34+D34 -> 210404 | I34: 5000 | J34: =(H34*0.1)-I34 -> 16040.4 | K34: =H34*0.2 -> 42080.8 | L34: =(H34-I34-J34-K34)/36 -> 4091.1889 | N34: 250 | O34: =(N34*365*0.45)*0.6 -> 24637.5 | P34: =(O34/H34)*100 -> 11.709616 | Q34: =H34/O34 -> 8.5399899
A35: LA-67 | B35: 360.1 | C35: 120 | D35: =C35*B35 -> 43212 | E35: Barnhouse | F35: 85 | G35: 2000 | H35: =G35*F35+D35 -> 213212 | I35: 5000 | J35: =(H35*0.1)-I35 -> 16321.2 | K35: =H35*0.2 -> 42642.4 | L35: =(H35-I35-J35-K35)/36 -> 4145.7889 | N35: 250 | O35: =(N35*365*0.45)*0.6 -> 24637.5 | P35: =(O35/H35)*100 -> 11.5554 | Q35: =H35/O35 -> 8.6539625
A36: LA-69 | B36: 325.3 | C36: 120 | D36: =C36*B36 -> 39036 | E36: A-Frame | F36: 85 | G36: 2000 | H36: =G36*F36+D36 -> 209036 | I36: 5000 | J36: =(H36*0.1)-I36 -> 15903.6 | K36: =H36*0.2 -> 41807.2 | L36: =(H36-I36-J36-K36)/36 -> 4064.5889 | N36: 250 | O36: =(N36*365*0.45)*0.6 -> 24637.5 | P36: =(O36/H36)*100 -> 11.786247 | Q36: =H36/O36 -> 8.4844647
A37: LA-71 | B37: 335.4 | C37: 120 | D37: =C37*B37 -> 40248 | E37: A-Frame | F37: 85 | G37: 2000 | H37: =G37*F37+D37 -> 210248 | I37: 5000 | J37: =(H37*0.1)-I37 -> 16024.8 | K37: =H37*0.2 -> 42049.6 | L37: =(H37-I37-J37-K37)/36 -> 4088.1556 | N37: 250 | O37: =(N37*365*0.45)*0.6 -> 24637.5 | P37: =(O37/H37)*100 -> 11.718304 | Q37: =H37/O37 -> 8.533658
... A43: LA-83 | B43: 353.5 | C43: 120 | D43: =C43*B43 -> 42420 | E43: Barnhouse | F43: 85 | G43: 2000 | H43: =G43*F43+D43 -> 212420 | I43: 5000 | J43: =(H43*0.1)-I43 -> 16242 | K43: =H43*0.2 -> 42484 | L43: =(H43-I43-J43-K43)/36 -> 4130.3889 | N43: 250 | O43: =(N43*365*0.45)*0.6 -> 24637.5 | P43: =(O43/H43)*100 -> 11.598484 | Q43: =H43/O43 -> 8.6218163
A44: LA-85 | B44: 626.5 | C44: 120 | D44: =C44*B44 -> 75180 | E44: Barnhouse | F44: 145 | G44: 2000 | H44: =G44*F44+D44 -> 365180 | I44: 5000 | J44: =(H44*0.1)-I44 -> 31518 | K44: =H44*0.2 -> 73036 | L44: =(H44-I44-J44-K44)/36 -> 7100.7222 | M44: =(H44*0.08)/12 -> 2434.5333 | N44: 400 | O44: =(N44*365*0.45)*0.6 -> 39420 | P44: =(O44/H44)*100 -> 10.794677 | Q44: =H44/O44 -> 9.2638255
A45: LA-87 | B45: 721.9 | C45: 120 | D45: =C45*B45 -> 86628 | E45: Modern Flat-Roof | F45: 145 | G45: 2000 | H45: =G45*F45+D45 -> 376628 | I45: 5000 | J45: =(H45*0.1)-I45 -> 32662.8 | K45: =H45*0.2 -> 75325.6 | L45: =(H45-I45-J45-K45)/36 -> 7323.3222 | M45: =(H45*0.08)/12 -> 2510.8533 | N45: 400 | O45: =(N45*365*0.45)*0.6 -> 39420 | P45: =(O45/H45)*100 -> 10.466561 | Q45: =H45/O45 -> 9.5542364
...

Sheet Sheet2
A2: ალტერნატიული შეთავაზება | B2: ნაკვეთის კოდი | C2: ნაკვეთის ფართობი (მ2) | D2: მიწის 1მ2 ფასი | E2: მიწის ღირებულება $ | F2: სახლის სტილი | G2: სახლის ფართი (მ2) | H2: ობიექტის რეალიზაციის ფასი 1 მ2 $ | I2: საინვესტიცო ღირებულება | J2: ბეი - რეზერვი $ | K2: პირველი შენატანი 10% | L2: პოსტ-ჰენდოვერი (20%) | M2: ყოველთვიური (36 თვე) | N2: დღიური ფასი ($) | O2: პესიური წლიური წმინდა მოგება | P2: პესიმისტური Rental ROI % | Q2: პესიმისტურიუკუგება (წელი)
B3: LA-1 | C3: 702.4 | D3: 120 | E3: =D3*C3 -> 84288 | F3: 2 x Barn_55 (მაღალი ამონაგები) | G3: 110 | H3: 2000 | I3: =H3*G3+E3 -> 304288 | J3: 5000 | K3: =(I3*0.1)-J3 -> 25428.8 | L3: =I3*0.2 -> 60857.6 | M3: =(I3-J3-K3-L3)/36 -> 5916.7111 | N3: 400 | O3: =(N3*365*0.45)*0.6 -> 39420 | P3: =(O3/I3)*100 -> 12.954832 | Q3: =I3/O3 -> 7.7191273
B4: LA-3 | C4: 683.2 | D4: 120 | E4: =D4*C4 -> 81984 | F4: 2 x Barn_55 (მაღალი ამონაგები) | G4: 110 | H4: 2000 | I4: =H4*G4+E4 -> 301984 | J4: 5000 | K4: =(I4*0.1)-J4 -> 25198.4 | L4: =I4*0.2 -> 60396.8 | M4: =(I4-J4-K4-L4)/36 -> 5871.9111 | N4: 400 | O4: =(N4*365*0.45)*0.6 -> 39420 | P4: =(O4/I4)*100 -> 13.053672 | Q4: =I4/O4 -> 7.6606799
B5: LA-5 | C5: 652.7 | D5: 120 | E5: =D5*C5 -> 78324 | F5: 2 x Barn_55 (მაღალი ამონაგები) | G5: 110 | H5: 2000 | I5: =H5*G5+E5 -> 298324 | J5: 5000 | K5: =(I5*0.1)-J5 -> 24832.4 | L5: =I5*0.2 -> 59664.8 | M5: =(I5-J5-K5-L5)/36 -> 5800.7444 | N5: 400 | O5: =(N5*365*0.45)*0.6 -> 39420 | P5: =(O5/I5)*100 -> 13.213821 | Q5: =I5/O5 -> 7.5678336
B6: LA-7 | C6: 558.9 | D6: 120 | E6: =D6*C6 -> 67068 | F6: Modern Flat-Roof (პრემიუმ დიზაინი) | G6: 85 | H6: 2000 | I6: =H6*G6+E6 -> 237068 | J6: 5000 | K6: =(Sheet1!G193*0.1)-J3 -> -4800 | L6: =I6*0.2 -> 47413.6 | M6: =(I6-J6-K6-L6)/36 -> 5262.6222 | N6: 250 | O6: =(N6*365*0.45)*0.6 -> 24637.5 | P6: =(O6/I6)*100 -> 10.392588 | Q6: =I6/O6 -> 9.6222425
B7: LA-9 | C7: 561.5 | D7: 120 | E7: =D7*C7 -> 67380 | F7: Modern Flat-Roof (პრემიუმ დიზაინი) | G7: 85 | H7: 2000 | I7: =H7*G7+E7 -> 237380 | J7: 5000 | K7: =(Sheet1!G194*0.1)-J4 -> -4800 | L7: =I7*0.2 -> 47476 | M7: =(I7-J7-K7-L7)/36 -> 5269.5556 | N7: 250 | O7: =(N7*365*0.45)*0.6 -> 24637.5 | P7: =(O7/I7)*100 -> 10.378928 | Q7: =I7/O7 -> 9.6349061
B8: LA-11 | C8: 740.3 | D8: 120 | E8: =D8*C8 -> 88836 | F8: 2 x Barn_55 (მაღალი ამონაგები) | G8: 110 | H8: 2000 | I8: =H8*G8+E8 -> 308836 | J8: 5000 | K8: =(I8*0.1)-J8 -> 25883.6 | L8: =I8*0.2 -> 61767.2 | M8: =(I8-J8-K8-L8)/36 -> 6005.1444 | N8: 400 | O8: =(N8*365*0.45)*0.6 -> 39420 | P8: =(O8/I8)*100 -> 12.764056 | Q8: =I8/O8 -> 7.8345003
B9: LA-13 | C9: 953.6 | D9: 120 | E9: =D9*C9 -> 114432 | F9: 2 x Barn_55 (მაღალი ამონაგები) | G9: 110 | H9: 2000 | I9: =H9*G9+E9 -> 334432 | J9: 5000 | K9: =(I9*0.1)-J9 -> 28443.2 | L9: =I9*0.2 -> 66886.4 | M9: =(I9-J9-K9-L9)/36 -> 6502.8444 | N9: 400 | O9: =(N9*365*0.45)*0.6 -> 39420 | P9: =(O9/I9)*100 -> 11.78715 | Q9: =I9/O9 -> 8.4838153
B10: LA-15 | C10: 1084.1 | D10: 120 | E10: =D10*C10 -> 130092 | F10: 2 x Barn_55 (მაღალი ამონაგები) | G10: 110 | H10: 2000 | I10: =H10*G10+E10 -> 350092 | J10: 5000 | K10: =(I10*0.1)-J10 -> 30009.2 | L10: =I10*0.2 -> 70018.4 | M10: =(I10-J10-K10-L10)/36 -> 6807.3444 | N10: 400 | O10: =(N10*365*0.45)*0.6 -> 39420 | P10: =(O10/I10)*100 -> 11.259897 | Q10: =I10/O10 -> 8.8810756
B11: LA-17 | C11: 503.7 | D11: 120 | E11: =D11*C11 -> 60444 | F11: Modern Flat-Roof (პრემიუმ დიზაინი) | G11: 85 | H11: 2000 | I11: =H11*G11+E11 -> 230444 | J11: 5000 | K11: =(I11*0.1)-J11 -> 18044.4 | L11: =I11*0.2 -> 46088.8 | M11: =(I11-J11-K11-L11)/36 -> 4480.8556 | N11: 250 | O11: =(N11*365*0.45)*0.6 -> 24637.5 | P11: =(O11/I11)*100 -> 10.691318 | Q11: =I11/O11 -> 9.3533841
B12: LA-19 | C12: 413.4 | D12: 120 | E12: =D12*C12 -> 49608 | F12: A_55 (ეკონომ არჩევანი) | G12: 55 | H12: 2000 | I12: =H12*G12+E12 -> 159608 | J12: 5000 | K12: =(I12*0.1)-J12 -> 10960.8 | L12: =I12*0.2 -> 31921.6 | M12: =(I12-J12-K12-L12)/36 -> 3103.4889 | N12: 200 | O12: =(N12*365*0.45)*0.6 -> 19710 | P12: =(O12/I12)*100 -> 12.349005 | Q12: =I12/O12 -> 8.0978184
B13: LA-21 | C13: 393 | D13: 120 | E13: =D13*C13 -> 47160 | F13: A_55 (ეკონომ არჩევანი) | G13: 55 | H13: 2000 | I13: =H13*G13+E13 -> 157160 | J13: 5000 | K13: =(I13*0.1)-J13 -> 10716 | L13: =I13*0.2 -> 31432 | M13: =(I13-J13-K13-L13)/36 -> 3055.8889 | N13: 200 | O13: =(N13*365*0.45)*0.6 -> 19710 | P13: =(O13/I13)*100 -> 12.541359 | Q13: =I13/O13 -> 7.9736175
B14: LA-23 | C14: 404.7 | D14: 120 | E14: =D14*C14 -> 48564 | F14: A_55 (ეკონომ არჩევანი) | G14: 55 | H14: 2000 | I14: =H14*G14+E14 -> 158564 | J14: 5000 | K14: =(I14*0.1)-J14 -> 10856.4 | L14: =I14*0.2 -> 31712.8 | M14: =(I14-J14-K14-L14)/36 -> 3083.1889 | N14: 200 | O14: =(N14*365*0.45)*0.6 -> 19710 | P14: =(O14/I14)*100 -> 12.430312 | Q14: =I14/O14 -> 8.0448503
B15: LA-25 | C15: 485.3 | D15: 120 | E15: =D15*C15 -> 58236 | F15: Modern Flat-Roof (პრემიუმ დიზაინი) | G15: 85 | H15: 2000 | I15: =H15*G15+E15 -> 228236 | J15: 5000 | K15: =(Sheet1!G202*0.1)-J12 -> -4800 | L15: =I15*0.2 -> 45647.2 | M15: =(I15-J15-K15-L15)/36 -> 5066.3556 | N15: 250 | O15: =(N15*365*0.45)*0.6 -> 24637.5 | P15: =(O15/I15)*100 -> 10.794748 | Q15: =I15/O15 -> 9.2637646
B16: LA-27 | C16: 479.7 | D16: 120 | E16: =D16*C16 -> 57564 | F16: Modern Flat-Roof (პრემიუმ დიზაინი) | G16: 85 | H16: 2000 | I16: =H16*G16+E16 -> 227564 | J16: 5000 | K16: =(Sheet1!G203*0.1)-J13 -> -4800 | L16: =I16*0.2 -> 45512.8 | M16: =(I16-J16-K16-L16)/36 -> 5051.4222 | N16: 250 | O16: =(N16*365*0.45)*0.6 -> 24637.5 | P16: =(O16/I16)*100 -> 10.826625 | Q16: =I16/O16 -> 9.2364891
B17: LA-29 | C17: 652.9 | D17: 120 | E17: =D17*C17 -> 78348 | F17: 2 x Barn_55 (მაღალი ამონაგები) | G17: 110 | H17: 2000 | I17: =H17*G17+E17 -> 298348 | J17: 5000 | K17: =(I17*0.1)-J17 -> 24834.8 | L17: =I17*0.2 -> 59669.6 | M17: =(I17-J17-K17-L17)/36 -> 5801.2111 | N17: 400 | O17: =(N17*365*0.45)*0.6 -> 39420 | P17: =(O17/I17)*100 -> 13.212758 | Q17: =I17/O17 -> 7.5684424
B18: LA-31 | C18: 513.9 | D18: 120 | E18: =D18*C18 -> 61668 | F18: Modern Flat-Roof (პრემიუმ დიზაინი) | G18: 85 | H18: 2000 | I18: =H18*G18+E18 -> 231668 | J18: 5000 | K18: =(Sheet1!G205*0.1)-J15 -> -4800 | L18: =I18*0.2 -> 46333.6 | M18: =(I18-J18-K18-L18)/36 -> 5142.6222 | N18: 250 | O18: =(N18*365*0.45)*0.6 -> 24637.5 | P18: =(O18/I18)*100 -> 10.634831 | Q18: =I18/O18 -> 9.4030644
B19: LA-33 | C19: 451.8 | D19: 120 | E19: =D19*C19 -> 54216 | F19: Modern Flat-Roof (პრემიუმ დიზაინი) | G19: 85 | H19: 2000 | I19: =H19*G19+E19 -> 224216 | J19: 5000 | K19: =(Sheet1!G206*0.1)-J16 -> -4800 | L19: =I19*0.2 -> 44843.2 | M19: =(I19-J19-K19-L19)/36 -> 4977.0222 | N19: 250 | O19: =(N19*365*0.45)*0.6 -> 24637.5 | P19: =(O19/I19)*100 -> 10.988288 | Q19: =I19/O19 -> 9.1005987
B20: LA-35 | C20: 509 | D20: 120 | E20: =D20*C20 -> 61080 | F20: Modern Flat-Roof (პრემიუმ დიზაინი) | G20: 85 | H20: 2000 | I20: =H20*G20+E20 -> 231080 | J20: 5000 | K20: =(Sheet1!G207*0.1)-J17 -> -4800 | L20: =I20*0.2 -> 46216 | M20: =(I20-J20-K20-L20)/36 -> 5129.5556 | N20: 250 | O20: =(N20*365*0.45)*0.6 -> 24637.5 | P20: =(O20/I20)*100 -> 10.661892 | Q20: =I20/O20 -> 9.3791984
B21: LA-37 | C21: 464.4 | D21: 120 | E21: =D21*C21 -> 55728 | F21: Modern Flat-Roof (პრემიუმ დიზაინი) | G21: 85 | H21: 2000 | I21: =H21*G21+E21 -> 225728 | J21: 5000 | K21: =(Sheet1!G208*0.1)-J18 -> -4800 | L21: =I21*0.2 -> 45145.6 | M21: =(I21-J21-K21-L21)/36 -> 5010.6222 | N21: 250 | O21: =(N21*365*0.45)*0.6 -> 24637.5 | P21: =(O21/I21)*100 -> 10.914685 | Q21: =I21/O21 -> 9.1619685
B22: LA-39 | C22: 425.4 | D22: 120 | E22: =D22*C22 -> 51048 | F22: A_55 (ეკონომ არჩევანი) | G22: 55 | H22: 2000 | I22: =H22*G22+E22 -> 161048 | J22: 5000 | K22: =(I22*0.1)-J22 -> 11104.8 | L22: =I22*0.2 -> 32209.6 | M22: =(I22-J22-K22-L22)/36 -> 3131.4889 | N22: 200 | O22: =(N22*365*0.45)*0.6 -> 19710 | P22: =(O22/I22)*100 -> 12.238587 | Q22: =I22/O22 -> 8.1708777
B23: LA-41 | C23: 309 | D23: 120 | E23: =D23*C23 -> 37080 | F23: Barnhouse (კომფორტისთვის) | G23: 55 | H23: 2000 | I23: =H23*G23+E23 -> 147080 | J23: 5000 | K23: =(Sheet1!G210*0.1)-J20 -> -4800 | L23: =I23*0.2 -> 29416 | M23: =(I23-J23-K23-L23)/36 -> 3262.8889 | N23: 250 | O23: =(N23*365*0.45)*0.6 -> 24637.5 | P23: =(O23/I23)*100 -> 16.751088 | Q23: =I23/O23 -> 5.9697615
B24: LA-43 | C24: 470.5 | D24: 120 | E24: =D24*C24 -> 56460 | F24: Modern Flat-Roof (პრემიუმ დიზაინი) | G24: 85 | H24: 2000 | I24: =H24*G24+E24 -> 226460 | J24: 5000 | K24: =(Sheet1!G211*0.1)-J21 -> -4800 | L24: =I24*0.2 -> 45292 | M24: =(I24-J24-K24-L24)/36 -> 5026.8889 | N24: 250 | O24: =(N24*365*0.45)*0.6 -> 24637.5 | P24: =(O24/I24)*100 -> 10.879405 | Q24: =I24/O24 -> 9.1916794
B25: LA-45 | C25: 628.6 | D25: 120 | E25: =D25*C25 -> 75432 | F25: 2 x Barn_55 (მაღალი ამონაგები) | G25: 110 | H25: 2000 | I25: =H25*G25+E25 -> 295432 | J25: 5000 | K25: =(Sheet1!G212*0.1)-J22 -> -4800 | L25: =I25*0.2 -> 59086.4 | M25: =(I25-J25-K25-L25)/36 -> 6559.6 | N25: 400 | O25: =(N25*365*0.45)*0.6 -> 39420 | P25: =(O25/I25)*100 -> 13.343172 | Q25: =I25/O25 -> 7.4944698
B26: LA-47 | C26: 652.1 | D26: 120 | E26: =D26*C26 -> 78252 | F26: 2 x Barn_55 (მაღალი ამონაგები) | G26: 110 | H26: 2000 | I26: =H26*G26+E26 -> 298252 | J26: 5000 | K26: =(I26*0.1)-J26 -> 24825.2 | L26: =I26*0.2 -> 59650.4 | M26: =(I26-J26-K26-L26)/36 -> 5799.3444 | N26: 400 | O26: =(N26*365*0.45)*0.6 -> 39420 | P26: =(O26/I26)*100 -> 13.217011 | Q26: =I26/O26 -> 7.5660071
B27: LA-49 | C27: 584.2 | D27: 120 | E27: =D27*C27 -> 70104 | F27: Modern Flat-Roof (პრემიუმ დიზაინი) | G27: 85 | H27: 2000 | I27: =H27*G27+E27 -> 240104 | J27: 5000 | K27: =(Sheet1!G214*0.1)-J24 -> -4800 | L27: =I27*0.2 -> 48020.8 | M27: =(I27-J27-K27-L27)/36 -> 5330.0889 | N27: 250 | O27: =(N27*365*0.45)*0.6 -> 24637.5 | P27: =(O27/I27)*100 -> 10.261178 | Q27: =I27/O27 -> 9.7454693
B28: LA-51 | C28: 443.3 | D28: 120 | E28: =D28*C28 -> 53196 | F28: A_55 (ეკონომ არჩევანი) | G28: 55 | H28: 2000 | I28: =H28*G28+E28 -> 163196 | J28: 5000 | K28: =(I28*0.1)-J28 -> 11319.6 | L28: =I28*0.2 -> 32639.2 | M28: =(I28-J28-K28-L28)/36 -> 3173.2556 | N28: 200 | O28: =(N28*365*0.45)*0.6 -> 19710 | P28: =(O28/I28)*100 -> 12.077502 | Q28: =I28/O28 -> 8.2798579
B29: LA-53 | C29: 348.6 | D29: 120 | E29: =D29*C29 -> 41832 | F29: Barnhouse (კომფორტისთვის) | G29: 55 | H29: 2000 | I29: =H29*G29+E29 -> 151832 | J29: 5000 | K29: =(Sheet1!G216*0.1)-J26 -> -4800 | L29: =I29*0.2 -> 30366.4 | M29: =(I29-J29-K29-L29)/36 -> 3368.4889 | N29: 200 | O29: =(N29*365*0.45)*0.6 -> 19710 | P29: =(O29/I29)*100 -> 12.981453 | Q29: =I29/O29 -> 7.7032978
B30: LA-55 | C30: 298 | D30: 120 | E30: =D30*C30 -> 35760 | F30: Barnhouse (კომფორტისთვის) | G30: 55 | H30: 2000 | I30: =H30*G30+E30 -> 145760 | J30: 5000 | K30: =(Sheet1!G217*0.1)-J27 -> -4800 | L30: =I30*0.2 -> 29152 | M30: =(I30-J30-K30-L30)/36 -> 3233.5556 | N30: 200 | O30: =(N30*365*0.45)*0.6 -> 19710 | P30: =(O30/I30)*100 -> 13.522228 | Q30: =I30/O30 -> 7.3952308
B31: LA-57 | C31: 366 | D31: 120 | E31: =D31*C31 -> 43920 | F31: A_55 (ეკონომ არჩევანი) | G31: 55 | H31: 2000 | I31: =H31*G31+E31 -> 153920 | J31: 5000 | K31: =(I31*0.1)-J31 -> 10392 | L31: =I31*0.2 -> 30784 | M31: =(I31-J31-K31-L31)/36 -> 2992.8889 | N31: 200 | O31: =(N31*365*0.45)*0.6 -> 19710 | P31: =(O31/I31)*100 -> 12.805353 | Q31: =I31/O31 -> 7.8092339
B32: LA-59 | C32: 369.6 | D32: 120 | E32: =D32*C32 -> 44352 | F32: A_55 (ეკონომ არჩევანი) | G32: 55 | H32: 2000 | I32: =H32*G32+E32 -> 154352 | J32: 5000 | K32: =(I32*0.1)-J32 -> 10435.2 | L32: =I32*0.2 -> 30870.4 | M32: =(I32-J32-K32-L32)/36 -> 3001.2889 | N32: 200 | O32: =(N32*365*0.45)*0.6 -> 19710 | P32: =(O32/I32)*100 -> 12.769514 | Q32: =I32/O32 -> 7.8311517
B33: LA-61 | C33: 385.3 | D33: 120 | E33: =D33*C33 -> 46236 | F33: A_55 (ეკონომ არჩევანი) | G33: 55 | H33: 2000 | I33: =H33*G33+E33 -> 156236 | J33: 5000 | K33: =(I33*0.1)-J33 -> 10623.6 | L33: =I33*0.2 -> 31247.2 | M33: =(I33-J33-K33-L33)/36 -> 3037.9222 | N33: 200 | O33: =(N33*365*0.45)*0.6 -> 19710 | P33: =(O33/I33)*100 -> 12.61553 | Q33: =I33/O33 -> 7.9267377
B34: LA-63 | C34: 381.8 | D34: 120 | E34: =D34*C34 -> 45816 | F34: A_55 (ეკონომ არჩევანი) | G34: 55 | H34: 2000 | I34: =H34*G34+E34 -> 155816 | J34: 5000 | K34: =(I34*0.1)-J34 -> 10581.6 | L34: =I34*0.2 -> 31163.2 | M34: =(I34-J34-K34-L34)/36 -> 3029.7556 | N34: 200 | O34: =(N34*365*0.45)*0.6 -> 19710 | P34: =(O34/I34)*100 -> 12.649535 | Q34: =I34/O34 -> 7.9054287
B35: LA-65 | C35: 336.7 | D35: 120 | E35: =D35*C35 -> 40404 | F35: Barnhouse (კომფორტისთვის) | G35: 55 | H35: 2000 | I35: =H35*G35+E35 -> 150404 | J35: 5000 | K35: =(Sheet1!G222*0.1)-J32 -> -4800 | L35: =I35*0.2 -> 30080.8 | M35: =(I35-J35-K35-L35)/36 -> 3336.7556 | N35: 200 | O35: =(N35*365*0.45)*0.6 -> 19710 | P35: =(O35/I35)*100 -> 13.104705 | Q35: =I35/O35 -> 7.6308473
B36: LA-67 | C36: 360.1 | D36: 120 | E36: =D36*C36 -> 43212 | F36: A_55 (ეკონომ არჩევანი) | G36: 55 | H36: 2000 | I36: =H36*G36+E36 -> 153212 | J36: 5000 | K36: =(I36*0.1)-J36 -> 10321.2 | L36: =I36*0.2 -> 30642.4 | M36: =(I36-J36-K36-L36)/36 -> 2979.1222 | N36: 200 | O36: =(N36*365*0.45)*0.6 -> 19710 | P36: =(O36/I36)*100 -> 12.864528 | Q36: =I36/O36 -> 7.773313
B37: LA-69 | C37: 325.3 | D37: 120 | E37: =D37*C37 -> 39036 | F37: Barnhouse (კომფორტისთვის) | G37: 55 | H37: 2000 | I37: =H37*G37+E37 -> 149036 | J37: 5000 | K37: =(Sheet1!G224*0.1)-J34 -> -4800 | L37: =I37*0.2 -> 29807.2 | M37: =(I37-J37-K37-L37)/36 -> 3306.3556 | N37: 200 | O37: =(N37*365*0.45)*0.6 -> 19710 | P37: =(O37/I37)*100 -> 13.224993 | Q37: =I37/O37 -> 7.5614409
B38: LA-71 | C38: 335.4 | D38: 120 | E38: =D38*C38 -> 40248 | F38: Barnhouse (კომფორტისთვის) | G38: 55 | H38: 2000 | I38: =H38*G38+E38 -> 150248 | J38: 5000 | K38: =(Sheet1!G225*0.1)-J35 -> -4800 | L38: =I38*0.2 -> 30049.6 | M38: =(I38-J38-K38-L38)/36 -> 3333.2889 | N38: 200 | O38: =(N38*365*0.45)*0.6 -> 19710 | P38: =(O38/I38)*100 -> 13.118311 | Q38: =I38/O38 -> 7.6229325
B39: LA-73 | C39: 293 | D39: 120 | E39: =D39*C39 -> 35160 | F39: Barnhouse (კომფორტისთვის) | G39: 55 | H39: 2000 | I39: =H39*G39+E39 -> 145160 | J39: 5000 | K39: =(Sheet1!G226*0.1)-J36 -> -4800 | L39: =I39*0.2 -> 29032 | M39: =(I39-J39-K39-L39)/36 -> 3220.2222 | N39: 200 | O39: =(N39*365*0.45)*0.6 -> 19710 | P39: =(O39/I39)*100 -> 13.578121 | Q39: =I39/O39 -> 7.3647894
B40: LA-75 | C40: 334.3 | D40: 120 | E40: =D40*C40 -> 40116 | F40: Barnhouse (კომფორტისთვის) | G40: 55 | H40: 2000 | I40: =H40*G40+E40 -> 150116 | J40: 5000 | K40: =(Sheet1!G227*0.1)-J37 -> -4800 | L40: =I40*0.2 -> 30023.2 | M40: =(I40-J40-K40-L40)/36 -> 3330.3556 | N40: 200 | O40: =(N40*365*0.45)*0.6 -> 19710 | P40: =(O40/I40)*100 -> 13.129846 | Q40: =I40/O40 -> 7.6162354
B41: LA-77 | C41: 433.6 | D41: 120 | E41: =D41*C41 -> 52032 | F41: A_55 (ეკონომ არჩევანი) | G41: 55 | H41: 2000 | I41: =H41*G41+E41 -> 162032 | J41: 5000 | K41: =(I41*0.1)-J41 -> 11203.2 | L41: =I41*0.2 -> 32406.4 | M41: =(I41-J41-K41-L41)/36 -> 3150.6222 | N41: 200 | O41: =(N41*365*0.45)*0.6 -> 19710 | P41: =(O41/I41)*100 -> 12.164264 | Q41: =I41/O41 -> 8.2208016
...
