Workbook
Name MY_FUNCTION1: LAMBDA(('Лист2'!$E$5+'Лист2'!$E$6='Лист2'!$E$7+'Лист2'!$E$9)*5%)

Sheet Лист1
A1: 1 | B1: ინვესტიციის შეჯამება Creen Canyon Eco Village & Resort
A2: 2 | B2: ფაზა 1: განვითარების ხარჯები (CAPEX)
A3: 3 | B3: მიწის შეძენის ღირებულება | D3: ='Лист2'!E3+'Лист2'!E2 -> 6000000
A4: 4 | B4: მშენებლობის საერთო ღირებულება | D4: ='Лист2'!E5+'Лист2'!E6+'Лист2'!E7+'Лист2'!E9+'Лист2'!E10 -> 28058625
A5: 5 | B5: ინვესტიციის საერთო ღირებულება | D5: ='Лист2'!E11 -> 34058625
A7: 1 | B7: ფაზა 2: გაყიდვები და მოგებაზე გასვლა
A8: 2 | B8: გაყიდვების მთლიანი შემოსავალი (აპარტამენტები + რეზიდენციები) | D8: ='Лист3'!G10 -> 44331690
A9: 3 | B9: მინუს: მარკეტინგის და გაყიდვების ხარჯები (10%) | D9: =10%*D8 -> 4433169
A10: 4 | B10: მინუს: კაპიტალური ხარჯები სუშთა მოგება | D10: 5,839,896
A11: 5 | B11: საკუთრებაში აქტივების ღირებულება (კომერციული) | D11: ='Лист3'!E31 -> 6000000
A13: 1 | B13: ფაზა 3: წლიური ოპერაციები (განმეორებადი)
A14: 2 | B14: წლიური შემოსავალი გაქირავების მართვიდან | D14: ='Лист3'!D25 -> 857779.2
A15: 3 | B15: წლიური შემოსავალი კომერციული ოპერაციებიდან | D15: ='Лист3'!E30 -> 712500
A16: 4 | B16: წლიური წმინდა შემოსავალი | D16: =D14+D15 -> 1570279.2
A19: 1 | B19: ნაკვეთი ს/ნ | D19: 85.19.23.326
A20: 2 | B20: სარეალიზაციო
A21: 3 | B21: ნაკვეთი 172 ცალი | C21: მ2 | D21: 81818
A22: 4 | B22: კომერციული | C22: მ2 | D22: 29970
A23: 5 | B23: გზები | C23: მ2 | D23: 21723
A24: 6 | B24: რეკრიაცია | C24: მ2 | D24: 16489
A25: 7 | B25: სრული ჯამი | C25: მ2 | D25: 150000

Sheet Лист2
B1: განვითარების ბიუჯეტის დაყოფა | C1: ფართი (მ²) | D1: $/მ² | E1: ჯამი
A2: 1 | B2: მიწის შეძენა | C2: 150000 | D2: 35 | E2: =D2*C2 -> 5250000
A3: 2 | B3: სრული პაკეტი (არქიტექტურა, ნებართვები,მართვის მოდელი) | C3: 150000 | D3: 5 | E3: =D3*C3 -> 750000
B4: 2. მშენებლობა (მყარი ხარჯები) | E4: =D4*C4 -> 0
A5: 1 | B5: საცხოვრებელი სახლები (172 ერთეული) | C5: 16550 | D5: 1200 | E5: =D5*C5 -> 19860000
A6: 2 | B6: აპარტ-სასტუმრო (100 ერთეული) | C6: 3375 | D6: 1100 | E6: =D6*C6 -> 3712500
A7: 3 | B7: კომერციული შენობები (დასასვენებელი, სპა) | C7: 3000 | D7: 800 | E7: =D7*C7 -> 2400000
B8: 3. ინფრასტრუქტურა | E8: =D8*C8 -> 0
A9: 1 | B9: გზები, ელექტროენერგია, წყალი, ლანდშაფტი | C9: 150000 | D9: 5 | E9: =D9*C9 -> 750000
A10: 2 | B10: 4. გაუთვალისწინებელი (გაუთვალისწინებელი) | D10: 0.05 | E10: =D10*(E5+E6+E7+E9) -> 1336125
A11: 3 | B11: პროექტის საერთო ღირებულება | E11: =SUM(E2:E10) -> 34058625

Sheet Лист3
B1: ტიპი | C1: რაოდენობა | D1: საშ. ფართი (m2) | E1: ჯამი m2 | F1: საშ. ფასი ($/m2) | G1: ჯამი $
B2: Eco Cabin (Loft) | C2: 44 | D2: 60 | E2: 2640 | F2: 1850 | G2: =F2*E2 -> 4884000
B3: Eco Cottage | C3: 75 | D3: 90 | E3: 6750 | F3: 1850 | G3: =F3*E3 -> 12487500
B4: Comfort | C4: 29 | D4: 120 | E4: 3480 | F4: 1850 | G4: =F4*E4 -> 6438000
B5: Comfort+ (60+60) | C5: 14 | D5: 120 | E5: 1680 | F5: 1850 | G5: =F5*E5 -> 3108000
B6: LUX Grand Villa | C6: 10 | D6: 200 | E6: 2000 | F6: 1850 | G6: =F6*E6 -> 3700000
B7: სტუდიო | C7: 75 | D7: 35 | E7: 2625 | F7: 1850 | G7: =F7*E7 -> 4856250
B8: ერთ საძინებლიანი აპარტ. | C8: 25 | D8: 50 | E8: 1250 | F8: 1850 | G8: =F8*E8 -> 2312500
B9: ნაკვეთის სარეალიზაციო ჯამი | C9: 172 | E9: 81818 | F9: 80 | G9: =F9*E9 -> 6545440
B10: სულ ჯამი | C10: =C9+C8+C7 -> 272 | G10: =SUM(G2:G9) -> 44331690
B16: დასახელება | C16: მაჩვენებელი | D16: მნიშვნელობა
B17: მთლიანი გასაქირავებელი იუნიტების ჯამი | C17: ცალი | D17: =C10 -> 272
B18: საშუალო დღიური განაკვეთი (ADR) | C18: ღირებულება | D18: 120
B19: დატვირთვის მაჩვენებელი (წლიური) | C19: დაშვება | D19: 0.45
B20: მთლიანი გაქირავების შემოსავალი | C20: $ | D20: =E36 -> 5361120
B21: მართვის საფასური (Management Fee) 40% | C21: $ | D21: =G36 -> 2144448
B22: ოპერირების საფასური (Booking/Airbnb) 15% | C22: $ | D22: =D20*15% -> 804168
B23: ოპერატიული ხარჯები (Utilities & Maint.) 5% | C23: $ | D23: =D20*5% -> 268056
B24: ქირავნობის წმინდა მოგება 20% | C24: $ | D24: =D21-D22-D23 -> 1072224
B25: მინუს ზედნადები ხარჯი | D25: =D24*80% -> 857779.2
B27: დასახელება | C27: დაშვება/ფართი | D27: ფასი $ | E27: ჯამი $
B28: საკუთრებაში არსებული კომერციული ფართი | C28: 3000.00 | D28: 900 | E28: $ 2,700,000
B29: წლიური ბრუნვა (F&B, SPA, ატრაქციონები) | C29: =E50 -> 2850000
B30: წმინდა მოგების მარჟა | C30: 0.25 | E30: =C29*C30 -> 712500
B31: წმინდა კომერციული მოგება სარეალიზაციო | C31: 3000 | D31: 2000 | E31: =D31*C31 -> 6000000
B35: წელი | C35: დატვირთვა | D35: ფასი | E35: შემოსავალი | F35: ხარჯი | G35: მოგება | H35: ROI
B36: 1 | C36: 0.45 | D36: 120 | E36: =D17*D36*365*C36 -> 5361120 | F36: =E36*60% -> 3216672 | G36: =E36-F36 -> 2144448 | H36: =G10/F36*0.01 -> 0.1378185
B37: 2 | C37: =C36*1.03 -> 0.4635 | D37: =D36*1.03 -> 123.6 | E37: =D17*D37*365*C37 -> 5687612.2 | F37: =E37*60% -> 3412567.3 | G37: =E37-F37 -> 2275044.9
B38: 3 | C38: =C37*1.03 -> 0.477405 | D38: =D37*1.03 -> 127.308 | E38: =D17*D38*365*C38 -> 6033987.8 | F38: =E38*60% -> 3620392.7 | G38: =E38-F38 -> 2413595.1
B39: 4 | C39: =C38*1.03 -> 0.49172715 | D39: =D38*1.03 -> 131.12724 | E39: =D17*D39*365*C39 -> 6401457.6 | F39: =E39*60% -> 3840874.6 | G39: =E39-F39 -> 2560583.1
B40: 5 | C40: =C39*1.03 -> 0.50647896 | D40: =D39*1.03 -> 135.06106 | E40: =D17*D40*365*C40 -> 6791306.4 | F40: =E40*60% -> 4074783.9 | G40: =E40-F40 -> 2716522.6
B44: ობიექტის ტიპი | C44: ლოკაცია / ფართი | D44: შემოსავლის წყარო | E44: წლიური ბრუნვა | F44: მოგების მარჟა | G44: წმინდა მოგება
B45: მთავარი რესტორანი + Lounge | C45: 900m (შიდა) | D45: კვება (F&B) ჯამური | E45: 1500000 | F45: 0.25 | G45: =E45*F45 -> 375000
B46: "Canyon View" რესტორანი | C46: გარე ტერასა | D46: ატრაქციონები (Ice + 5D) | E46: 350000 | F46: 0.5 | G46: =E46*F46 -> 175000
B47: SPA & Wellness | C47: 800m (შიდა) | D47: SPA & Wellness | E47: 400000 | F47: 0.3 | G47: =E47*F47 -> 120000
B48: ყინულის მოედანი (Ice Rink) | C48: გარე (სეზონური) | D48: MICE (ივენთები) | E48: 250000 | F48: 0.4 | G48: =E48*F48 -> 100000
B49: 5D ობსერვატორია / კინო | C49: 200m (შიდა) | D49: იჯარა/Retail | E49: 80000 | F49: 1 | G49: =E49*F49 -> 80000
B50: MICE / ივენთ ჰოლი | C50: 400m (შიდა) | D50: სულ ჯამი | E50: 2850000 | F50: 29~33% | G50: =SUM(G45:G49) -> 850000
B51: Retail / სერვისები | C51: 200m(შიდა)

Sheet Лист4
D1: Description | E1: Land Area | F1: House Area | G1: Price (Turnkey) | H1: Land | I1: Total | J1: Status
B2: „ | D2: Alpine Studio | E2: Shared | F2: 35 | G2: $64,750 | I2: $64,750 | J2: ✅ Available
B3: 25 | D3: Grand Suite | E3: Shared | F3: 50 | G3: $92,500 | I3: $92,500 | J3: ✅ Available
B4: 44 | D4: Eco Cabin (Loft) | E4: 300-400 m² | F4: 60 | G4: $111,000 | H4: $28,000 | I4: $139,000 | J4: ✅ Available+land
B5: 75 | D5: Eco Cottage | E5: 400-500 m² | F5: 90 | G5: $166,500 | H5: $36,000 | I5: $202,500 | J5: ✅ Available+land
B6: 29 | D6: Comfort | E6: 500-600 m² | F6: 120 | G6: $222,000 | H6: $44,000 | I6: $266,000 | J6: ✅ Available+land
B7: 14 | D7: Comfort+ (60+60) | E7: 600-700 m² | F7: 120 | G7: $222,000 | H7: $52,000 | I7: $274,000 | J7: ✅ Available+land
B8: 10 | D8: LUX Grand Villa | E8: 700 -m² | F8: 200 | G8: $370,000 | H8: $60,000 | I8: $430,000 | J8: ✅ Available+land
A11: აპარტამენტის აღჭურვილობის სრული ხარჯთაღრიცხვა
A12: კატეგორია | C12: # | D12: დასახელება | E12: რაოდენობა | F12: სავარაუდო ფასი (1 ცალი, GEL) | G12: სულ (GEL)
A13: ა) ჰოლის ნაწილი
C14: 1 | D14: შემოსასვლელის კარადა სარკით | E14: 1 | F14: 500 | G14: 500
C15: 2 | D15: ტანსაცმლის საკიდი (კედლის) | E15: 1 | F15: 50 | G15: 50
C16: 3 | D16: ფეხსაცმლის კოვზი | E16: 1 | F16: 10 | G16: 10
C17: 4 | D17: თეთრეულის ტომარა | E17: 1 | F17: 30 | G17: 30
C18: 5 | D18: უთო | E18: 1 | F18: 150 | G18: 150
C19: 6 | D19: საუთოვებელი მაგიდა | E19: 1 | F19: 120 | G19: 120
D20: ჰოლის ნაწილის ჯამი | G20: 860
A21: ბ) საცხოვრებელი ნაწილი
C22: 1 | D22: ორადგილიანი გასაშლელი დივანი | E22: 1 | F22: 1.2 | G22: 1.2
C23: 2 | D23: ტუმბო (ჟურნალის მაგიდა) | E23: 1 | F23: 200 | G23: 200
C24: 3 | D24: სამუშაო მაგიდა სკამით | E24: 1 | F24: 400 | G24: 400
C25: 4 | D25: ტელევიზორის სადგამი | E25: 1 | F25: 300 | G25: 300
C26: 5 | D26: სანათი (ტორშერი) | E26: 1 | F26: 180 | G26: 180
C27: 6 | D27: ფარდა (დღის და ღამის) | E27: 1 კომპ. | F27: 350 | G27: 350
C28: 7 | D28: ფარდის საკიდი (კარნიზი) | E28: 1 | F28: 80 | G28: 80
C29: 8 | D29: სასადილო მაგიდა | E29: 1 | F29: 400 | G29: 400
C30: 9 | D30: სასადილო მაგიდის სკამი | E30: 4 | F30: 150 | G30: 600
C31: 10 | D31: ტელევიზორი (43" Smart TV) | E31: 1 | F31: 900 | G31: 900
C32: 11 | D32: კონდიციონერება, გათბობა | E32: - | F32: შენობის ნაწილი | G32: 0
C33: 12 | D33: ტელეფონი (სასტუმროს) | E33: 1 | F33: 80 | G33: 80
C34: 13 | D34: ვაზა (დეკორატიული) | E34: 1 | F34: 50 | G34: 50
D35: საცხოვრებელი ნაწილის ჯამი | G35: 4.74
A36: გ) საძინებლის ნაწილი
C37: 1 | D37: გარდერობი სარკით | E37: 1 | F37: 600 | G37: 600
C38: 2 | D38: ორადგილიანი საწოლი + ლეიბი | E38: 1 | F38: 1.5 | G38: 1.5
C39: 3 | D39: საწოლის ტუმბო | E39: 2 | F39: 150 | G39: 300
C40: 4 | D40: ნათურა საწოლის ტუმბოსთვის | E40: 2 | F40: 120 | G40: 240
C41: 5 | D41: საძინებლის სარკე | E41: 1 | F41: 200 | G41: 200
C42: 6 | D42: სკამი პარფიუმერიისთვის | E42: 1 | F42: 180 | G42: 180
...

Sheet Лист5
A1: წალკის რაიონის ტურისტული ბაზრის კვლევიდან გამომდინარე, სასტუმრო ნომრის გაქირავების პესიმისტური ანალიზი გათვლილი 5 წელზე | J1: ოპტიმისტური ანალიზი გათვლილი 5 წელზე
A2: აპარტამენტი | B2: Alpine Studio | J2: აპარტამენტი | K2: Alpine Studio
A3: ფართი მ2 | B3: 35 | J3: ფართი მ2 | K3: 35
A4: ფასი | B4: 64750 | J4: ფასი | K4: 64750
A5: ADR-$ | B5: 80 | J5: ADR-$ | K5: 80
A6: 1მ2 ფასი $ | B6: 1850 | J6: 1მ2 ფასი $ | K6: 1850
A7: რაოდნობა | B7: 75 | J7: რაოდნობა | K7: 75
A8: წელი | B8: დატვირთვა | C8: ფასი | D8: შემოსავალი | E8: ხარჯი | F8: მოგება | G8: ROI | H8: ინ. უკუგება | J8: წელი | K8: დატვირთვა | L8: ფასი | M8: შემოსავალი | N8: ხარჯი | O8: მოგება | P8: ROI | Q8: ინ. უკუგება
A9: 1 | B9: 0.45 | C9: 80 | D9: 13140 | E9: -5256 | F9: 7884 | G9: 0.12 | J9: 1 | K9: 0.45 | L9: 80 | M9: 13140 | N9: -5256 | O9: 7884 | P9: 0.12
A10: 2 | B10: 0.46 | C10: 80 | D10: 13534 | E10: -5414 | F10: 8121 | G10: 0.13 | J10: 2 | K10: 0.5 | L10: 88 | M10: 15899 | N10: -6360 | O10: 9540 | P10: 0.15
A11: 3 | B11: 0.48 | C11: 80 | D11: 13940 | E11: -5576 | F11: 8364 | G11: 0.13 | J11: 3 | K11: 0.54 | L11: 97 | M11: 19238 | N11: -7695 | O11: 11543 | P11: 0.18
A12: 4 | B12: 0.49 | C12: 80 | D12: 14358 | E12: -5743 | F12: 8615 | G12: 0.13 | J12: 4 | K12: 0.6 | L12: 106 | M12: 23278 | N12: -9311 | O12: 13967 | P12: 0.22
A13: 5 | B13: 0.51 | C13: 80 | D13: 14789 | E13: -5916 | F13: 8874 | G13: 0.14 | H13: 7 | J13: 5 | K13: 0.66 | L13: 117 | M13: 28167 | N13: -11267 | O13: 16900 | P13: 0.26 | Q13: 4
A16: აპარტამენტი | B16: Alpine 1+1 bedroom | J16: აპარტამენტი | K16: Alpine 1+1 bedroom
A17: ფართი მ2 | B17: 50 | J17: ფართი მ2 | K17: 50
A18: ფასი | B18: 92500 | J18: ფასი | K18: 92500
A19: ADR-$ | B19: 100 | J19: ADR-$ | K19: 100
A20: 1მ2 ფასი $ | B20: 1850 | J20: 1მ2 ფასი $ | K20: 1850
A21: რაოდენობა | B21: 25 | J21: რაოდენობა | K21: 25
A22: წელი | B22: დატვირთვა | C22: ფასი | D22: შემოსავალი | E22: ხარჯი | F22: მოგება | G22: ROI | H22: ინ. უკუგება | J22: წელი | K22: დატვირთვა | L22: ფასი | M22: შემოსავალი | N22: ხარჯი | O22: მოგება | P22: ROI | Q22: ინ. უკუგება
A23: 1 | B23: 0.45 | C23: 100 | D23: 16425 | E23: -6570 | F23: 9855 | G23: 0.11 | J23: 1 | K23: 0.45 | L23: 100 | M23: 16425 | N23: -6570 | O23: 9855 | P23: 0.11
A24: 2 | B24: 0.46 | C24: 100 | D24: 16918 | E24: -6767 | F24: 10151 | G24: 0.11 | J24: 2 | K24: 0.5 | L24: 110 | M24: 19874 | N24: -7950 | O24: 11925 | P24: 0.13
A25: 3 | B25: 0.48 | C25: 100 | D25: 17425 | E25: -6970 | F25: 10455 | G25: 0.11 | J25: 3 | K25: 0.54 | L25: 121 | M25: 24048 | N25: -9619 | O25: 14429 | P25: 0.16
A26: 4 | B26: 0.49 | C26: 100 | D26: 17948 | E26: -7179 | F26: 10769 | G26: 0.12 | J26: 4 | K26: 0.6 | L26: 133 | M26: 29098 | N26: -11639 | O26: 17459 | P26: 0.19
A27: 5 | B27: 0.51 | C27: 100 | D27: 18486 | E27: -7395 | F27: 11092 | G27: 0.12 | H27: 8 | J27: 5 | K27: 0.66 | L27: 146 | M27: 35208 | N27: -14083 | O27: 21125 | P27: 0.23 | Q27: 4
A31: Eco Cabin (Loft) | B31: 2 bedroom | J31: Eco Cabin (Loft) | K31: 2 bedroom
A32: ნაკვეთი(300-400)მ2 | B32: 24500 | J32: ნაკვეთი(300-400)მ2 | K32: 24500
A33: ფართი მ2 | B33: 60 | J33: ფართი მ2 | K33: 60
A34: ფასი | B34: 129500 | J34: ფასი | K34: 129500
A35: ADR-$ | B35: 150 | J35: ADR-$ | K35: 150
A36: 1მ2 ფასი $ | B36: 1750 | J36: 1მ2 ფასი $ | K36: 1750
A37: რაოდენობა | B37: 44 | J37: რაოდენობა | K37: 44
A38: წელი | B38: დატვირთვა | C38: ფასი | D38: შემოსავალი | E38: ხარჯი | F38: მოგება | G38: ROI | H38: ინ. უკუგება | J38: წელი | K38: დატვირთვა | L38: ფასი | M38: შემოსავალი | N38: ხარჯი | O38: მოგება | P38: ROI | Q38: ინ. უკუგება
A39: 1 | B39: 0.45 | C39: 150 | D39: 24638 | E39: -9855 | F39: 14783 | G39: 0.11 | J39: 1 | K39: 0.45 | L39: 150 | M39: 24638 | N39: -9855 | O39: 14783 | P39: 0.11
A40: 2 | B40: 0.46 | C40: 150 | D40: 25377 | E40: -10151 | F40: 15226 | G40: 0.12 | J40: 2 | K40: 0.5 | L40: 165 | M40: 29811 | N40: -11925 | O40: 17887 | P40: 0.14
A41: 3 | B41: 0.48 | C41: 150 | D41: 26138 | E41: -10455 | F41: 15683 | G41: 0.12 | J41: 3 | K41: 0.54 | L41: 182 | M41: 36072 | N41: -14429 | O41: 21643 | P41: 0.17
A42: 4 | B42: 0.49 | C42: 150 | D42: 26922 | E42: -10769 | F42: 16153 | G42: 0.12 | J42: 4 | K42: 0.6 | L42: 200 | M42: 43647 | N42: -17459 | O42: 26188 | P42: 0.2
A43: 5 | B43: 0.51 | C43: 150 | D43: 27730 | E43: -11092 | F43: 16638 | G43: 0.13 | H43: 46241 | J43: 5 | K43: 0.66 | L43: 220 | M43: 52813 | N43: -21125 | O43: 31688 | P43: 0.24 | Q43: 46026
A46: Eco Cottage | B46: 3+1 bedroom | J46: Eco Cottage | K46: 3+1 bedroom
A47: ნაკვეთი(400-500)მ2 | B47: 31500 | J47: ნაკვეთი(400-500)მ2 | K47: 31500
...

Sheet Лист6
A1: Area 1 | B1: Unit | C1: m² | D1: Type | F1: Area 2 | G1: Unit | H1: m² | I1: Type | K1: Area 3 | L1: Unit | M1: m² | N1: Type | P1: Area 4 | Q1: Unit | R1: m² | S1: Type
A2: Area 1-1 | B2: LA-1 | C2: 702.4 | D2: Grand Villa | F2: Area 2-1 | G2: LB-2 | H2: 392.4 | I2: Eco Cabin | K2: Area 3-1 | L2: LB-1 | M2: 654.9 | N2: Lux | P2: Area 4-1 | Q2: LD-3 | R2: 491 | S2: Eco Cottage
A3: Area 1-2 | B3: LA-2 | C3: 683.2 | D3: Lux | F3: Area 2-2 | G3: LB-4 | H3: 491.7 | I3: Eco Cottage | K3: Area 3-2 | L3: LB-3 | M3: 384 | N3: Eco Cabin | P3: Area 4-2 | Q3: LD-4 | R3: 525.7 | S3: Comfort
A4: Area 1-3 | B4: LA-3 | C4: 635.8 | D4: Lux | F4: Area 2-3 | G4: LB-6 | H4: 557.8 | I4: Comfort | K4: Area 3-3 | L4: LB-5 | M4: 509.5 | N4: Comfort | P4: Area 4-3 | Q4: LD-5 | R4: 570 | S4: Comfort
A5: Area 1-4 | B5: LA-4 | C5: 542.8 | D5: Comfort | F5: Area 2-4 | G5: LB-8 | H5: 591.5 | I5: Comfort | K5: Area 3-4 | L5: LB-7 | M5: 599.2 | N5: Comfort | P5: Area 4-4 | Q5: LD-6 | R5: 570 | S5: Comfort
A6: Area 1-5 | B6: LA-5 | C6: 561.5 | D6: Comfort | F6: Area 2-5 | G6: LB-10 | H6: 608.4 | I6: Lux | K6: Area 3-5 | L6: LB-9 | M6: 565.3 | N6: Comfort | P6: Area 4-5 | Q6: LD-7 | R6: 741.9 | S6: Grand Villa
A7: Area 1-6 | B7: LA-6 | C7: 740.3 | D7: Grand Villa | F7: Area 2-6 | G7: LB-12 | H7: 609.8 | I7: Lux | K7: Area 3-6 | L7: LB-11 | M7: 491.1 | N7: Eco Cottage | P7: Area 4-6 | Q7: LG-1 | R7: 789.9 | S7: Grand Villa
A8: Area 1-7 | B8: LA-7 | C8: 953.6 | D8: Grand Villa | F8: Area 2-7 | G8: LB-14 | H8: 580.2 | I8: Comfort | K8: Area 3-7 | L8: LB-13 | M8: 466.5 | N8: Eco Cottage | P8: Area 4-7 | Q8: LG-2 | R8: 509.8 | S8: Comfort
A9: Area 1-8 | B9: LA-8 | C9: 1084.1 | D9: Grand Villa | F9: Area 2-8 | G9: LC-1 | H9: 567.2 | I9: Comfort | K9: Area 3-8 | L9: LB-15 | M9: 522.9 | N9: Comfort | P9: Area 4-8 | Q9: LG-3 | R9: 454.3 | S9: Eco Cottage
A10: Area 1-9 | B10: LF-1 | C10: 503.6 | D10: Comfort | F10: Area 2-9 | G10: LC-3 | H10: 548 | I10: Comfort | K10: Area 3-9 | L10: LC-2 | M10: 582.2 | N10: Comfort | P10: Area 4-9 | Q10: LG-4 | R10: 369.9 | S10: Eco Cabin
A11: Area 1-10 | B11: LF-2 | C11: 413.4 | D11: Eco Cottage | F11: Area 2-10 | G11: LC-5 | H11: 511.9 | I11: Comfort | K11: Area 3-10 | L11: LC-4 | M11: 557.3 | N11: Comfort | P11: Area 4-10 | Q11: LH-1 | R11: 558.5 | S11: Comfort
A12: Area 1-11 | B12: LF-3 | C12: 393 | D12: Eco Cabin | F12: Area 2-11 | G12: LC-7 | H12: 457.2 | I12: Eco Cottage | K12: Area 3-11 | L12: LC-6 | M12: 498.4 | N12: Eco Cottage | P12: Area 4-11 | Q12: LH-2 | R12: 408.2 | S12: Eco Cottage
A13: Area 1-12 | B13: LF-4 | C13: 404.7 | D13: Eco Cottage | F13: Area 2-12 | G13: LC-9 | H13: 381.9 | I13: Eco Cabin | K13: Area 3-12 | L13: LC-8 | M13: 438.1 | N13: Eco Cottage | P13: Area 4-12 | Q13: LH-3 | R13: 399 | S13: Eco Cabin
A14: Area 1-13 | B14: LF-5 | C14: 485.3 | D14: Eco Cottage | F14: Area 2-13 | G14: LC-11 | H14: 283.2 | I14: Eco Cabin | K14: Area 3-13 | L14: LC-10 | M14: 377.7 | N14: Eco Cabin | P14: Area 4-13 | Q14: LH-4 | R14: 389.8 | S14: Eco Cabin
A15: Area 1-14 | B15: LF-6 | C15: 479.7 | D15: Eco Cottage | F15: Area 2-14 | G15: LC-13 | H15: 504.5 | I15: Comfort | K15: Area 3-14 | L15: LC-12 | M15: 317.4 | N15: Eco Cabin | P15: Area 4-14 | Q15: LH-5 | R15: 380.5 | S15: Eco Cabin
A16: Area 1-15 | B16: LF-7 | C16: 652.9 | D16: Lux | F16: Area 2-15 | G16: LE-7 | H16: 643.2 | I16: Lux | K16: Area 3-15 | L16: LI-1 | M16: 426.8 | N16: Eco Cottage | P16: Area 4-15 | Q16: LH-6 | R16: 372.3 | S16: Eco Cabin
A17: Area 1-16 | B17: LF-8 | C17: 513.9 | D17: Comfort | F17: Area 2-16 | G17: LE-8 | H17: 538.8 | I17: Comfort | K17: Area 3-16 | L17: LI-3 | M17: 426.8 | N17: Eco Cottage | P17: Area 4-16 | Q17: LH-7 | R17: 370.5 | S17: Eco Cabin
A18: Area 1-17 | B18: LF-9 | C18: 451.8 | D18: Eco Cottage | F18: Area 2-17 | G18: LE-9 | H18: 376 | I18: Eco Cabin | K18: Area 3-17 | L18: LI-5 | M18: 426.8 | N18: Eco Cottage | P18: Area 4-17 | Q18: LH-8 | R18: 369.8 | S18: Eco Cabin
A19: Area 1-18 | B19: LF-10 | C19: 509 | D19: Comfort | F19: Area 2-18 | G19: LE-10 | H19: 359.3 | I19: Eco Cabin | K19: Area 3-18 | L19: LI-7 | M19: 426.8 | N19: Eco Cottage | P19: Area 4-18 | Q19: LH-9 | R19: 369.1 | S19: Eco Cabin
A20: Area 1-19 | B20: LF-11 | C20: 464.4 | D20: Eco Cottage | F20: Area 2-19 | G20: LE-11 | H20: 382.6 | I20: Eco Cabin | K20: Area 3-19 | L20: LI-9 | M20: 426.8 | N20: Eco Cottage | P20: Area 4-19 | Q20: LH-10 | R20: 369.1 | S20: Eco Cabin
A21: Area 1-20 | B21: LF-12 | C21: 425.4 | D21: Eco Cottage | F21: Area 2-20 | G21: LE-12 | H21: 402 | I21: Eco Cottage | K21: Area 3-20 | L21: LI-11 | M21: 426.8 | N21: Eco Cottage | P21: Area 4-20 | Q21: LH-11 | R21: 379.4 | S21: Eco Cabin
A22: Area 1-21 | B22: LF-13 | C22: 309 | D22: Eco Cabin | F22: Area 2-21 | G22: LE-13 | H22: 409.7 | I22: Eco Cottage | K22: Area 3-21 | L22: LK-1 | M22: 426.8 | N22: Eco Cottage | P22: Area 4-21 | Q22: LH-12 | R22: 392.9 | S22: Eco Cabin
A23: Area 1-22 | B23: LJ-1 | C23: 470.5 | D23: Eco Cottage | F23: Area 2-22 | G23: LE-14 | H23: 406 | I23: Eco Cottage | K23: Area 3-22 | L23: LK-3 | M23: 426.8 | N23: Eco Cottage | P23: Area 4-22 | Q23: LH-13 | R23: 398.4 | S23: Eco Cabin
A24: Area 1-23 | B24: LJ-2 | C24: 628.6 | D24: Lux | F24: Area 2-23 | G24: LE-15 | H24: 406.3 | I24: Eco Cottage | K24: Area 3-23 | L24: LK-5 | M24: 426.8 | N24: Eco Cottage | P24: Area 4-23 | Q24: LH-14 | R24: 377 | S24: Eco Cabin
A25: Area 1-24 | B25: LJ-3 | C25: 652.1 | D25: Lux | F25: Area 2-24 | G25: LE-16 | H25: 600.7 | I25: Lux | K25: Area 3-24 | L25: LK-7 | M25: 426.8 | N25: Eco Cottage | P25: Area 4-24 | Q25: LH-15 | R25: 342.3 | S25: Eco Cabin
A26: Area 1-25 | B26: LJ-4 | C26: 584.2 | D26: Comfort | F26: Area 2-25 | G26: LI-2 | H26: 433.3 | I26: Eco Cottage | K26: Area 3-25 | L26: LK-9 | M26: 428.7 | N26: Eco Cottage | P26: Area 4-25 | Q26: LH-16 | R26: 430.3 | S26: Eco Cottage
A27: Area 1-26 | B27: LJ-5 | C27: 443.3 | D27: Eco Cottage | F27: Area 2-26 | G27: LI-4 | H27: 426.8 | I27: Eco Cottage | K27: Area 3-26 | L27: LK-11 | M27: 467.1 | N27: Eco Cottage | P27: - | Q27: - | R27: 11329.6 | S27: -
A28: Area 1-27 | B28: LJ-6 | C28: 348.6 | D28: Eco Cabin | F28: Area 2-27 | G28: LI-6 | H28: 426.8 | I28: Eco Cottage | K28: Area 3-27 | L28: LD-1 | M28: 649.3 | N28: Lux | P28: - | Q28: - | R28: - | S28: -
A29: Area 1-28 | B29: LJ-7 | C29: 298 | D29: Eco Cabin | F29: Area 2-28 | G29: LI-8 | H29: 426.8 | I29: Eco Cottage | K29: Area 3-28 | L29: LD-2 | M29: 901.9 | N29: Grand Villa | P29: - | Q29: - | R29: - | S29: -
A30: Area 1-29 | B30: LL-1 | C30: 366 | D30: Eco Cabin | F30: Area 2-29 | G30: LI-10 | H30: 426.8 | I30: Eco Cottage | K30: Area 3-29 | L30: LE-1 | M30: 514.2 | N30: Comfort | P30: - | Q30: - | R30: - | S30: -
A31: Area 1-30 | B31: LL-2 | C31: 369.6 | D31: Eco Cabin | F31: Area 2-30 | G31: LI-12 | H31: 426.8 | I31: Eco Cottage | K31: Area 3-30 | L31: LE-2 | M31: 337.5 | N31: Eco Cabin | P31: - | Q31: - | R31: - | S31: -
A32: Area 1-31 | B32: LL-3 | C32: 385.3 | D32: Eco Cabin | F32: Area 2-31 | G32: LK-2 | H32: 426.8 | I32: Eco Cottage | K32: Area 3-31 | L32: LE-3 | M32: 396.9 | N32: Eco Cabin | P32: - | Q32: - | R32: - | S32: -
A33: Area 1-32 | B33: LL-4 | C33: 381.8 | D33: Eco Cabin | F33: Area 2-32 | G33: LK-4 | H33: 426.8 | I33: Eco Cottage | K33: Area 3-32 | L33: LE-4 | M33: 417.9 | N33: Eco Cottage | P33: - | Q33: - | R33: - | S33: -
A34: Area 1-33 | B34: LL-5 | C34: 336.7 | D34: Eco Cabin | F34: Area 2-33 | G34: LK-6 | H34: 426.8 | I34: Eco Cottage | K34: Area 3-33 | L34: LE-5 | M34: 412.8 | N34: Eco Cottage | P34: - | Q34: - | R34: - | S34: -
A35: Area 1-34 | B35: LL-6 | C35: 360.1 | D35: Eco Cabin | F35: Area 2-34 | G35: LK-8 | H35: 426.8 | I35: Eco Cottage | K35: Area 3-34 | L35: LE-6 | M35: 590.5 | N35: Comfort | P35: - | Q35: - | R35: - | S35: -
A36: Area 1-35 | B36: LO-1 | C36: 325.3 | D36: Eco Cabin | F36: Area 2-35 | G36: LK-10 | H36: 426.8 | I36: Eco Cottage | K36: Area 3-35 | L36: LM-2 | M36: 420 | N36: Eco Cottage | P36: - | Q36: - | R36: - | S36: -
A37: Area 1-36 | B37: LO-2 | C37: 335.4 | D37: Eco Cabin | F37: Area 2-36 | G37: LK-12 | H37: 412.6 | I37: Eco Cottage | K37: Area 3-36 | L37: LM-3 | M37: 420 | N37: Eco Cottage | P37: - | Q37: - | R37: - | S37: -
A38: Area 1-37 | B38: LO-3 | C38: 293 | D38: Eco Cabin | F38: Area 2-37 | G38: LM-1 | H38: 539.7 | I38: Comfort | K38: Area 3-37 | L38: LM-4 | M38: 420 | N38: Eco Cottage | P38: - | Q38: - | R38: - | S38: -
A39: Area 1-38 | B39: LO-4 | C39: 334.3 | D39: Eco Cabin | F39: Area 2-38 | G39: LN-1 | H39: 612.6 | I39: Lux | K39: Area 3-38 | L39: LM-5 | M39: 420 | N39: Eco Cottage | P39: - | Q39: - | R39: - | S39: -
A40: Area 1-39 | B40: LO-5 | C40: 433.6 | D40: Eco Cottage | F40: Area 2-39 | G40: LN-2 | H40: 422.6 | I40: Eco Cottage | K40: Area 3-39 | L40: LM-6 | M40: 420 | N40: Eco Cottage | P40: - | Q40: - | R40: - | S40: -
...

Sheet Лист7
A2: პირველი ზოლო კანიონისპირას | B2: დინამიური გაყიდვა | E2: ფასი | F2: ნაკვეთის მ2 | G2: ჯამი | K2: მ2 | L2: ჯამი მ2 | M2: ფასი | N2: ჯამი
B3: მ2 | C3: 24982.2 | E3: $ 100 | G3: $ 2,498,220 | I3: დინამიური ცხრილიდან | J3: 172 | K3: 17030 | L3: 81.819 | N3: $ 40,981,664
A4: ერთეული | B4: ცალი | C4: 49 | I4: სტუდიო | J4: 75 | K4: 35 | L4: 2.625 | M4: 1850 | N4: $ 4,856,250
A5: Eco Cabin (Loft) | C5: 15 | D5: $ 900 | E5: $ 2,200 | G5: $ 1,980,000 | I5: ერთ საძინებლიანი აპარტ. | J5: 25 | K5: 50 | L5: 1.25 | M5: 1850 | N5: $ 2,312,500
A6: Eco Cottage | C6: 15 | D6: $ 1,350 | E6: $ 2,200 | G6: $ 2,970,000 | N6: $ 48,150,414
A7: Comfort | C7: 7 | D7: $ 840 | E7: $ 2,200 | G7: $ 1,848,000
A8: Comfort+ (60+60) | C8: 6 | D8: $ 720 | E8: $ 2,200 | G8: $ 1,584,000
A9: LUX Grand Villa | C9: 6 | D9: $ 1,200 | E9: $ 2,200 | G9: $ 2,640,000
D10: $ 5,010 | G10: $ 13,520,220 | I10: განვითარების ბიუჯეტის დაყოფა | J10: ფართი (მ²) | K10: $/მ² | L10: ჯამი
H11: 1 | I11: მიწის შეძენა | J11: 150000 | K11: 35 | L11: $ 5,250,000
H12: 2 | I12: სრული პაკეტი (არქიტექტურა, ნებართვები,მართვის მოდელი) | J12: 150000 | K12: 5 | L12: $ 750,000
I13: 2. მშენებლობა (მყარი ხარჯები)
A14: მეორე ზოლი | B14: მ2 | C14: 23319.2 | E14: $ 80 | G14: $ 1,865,536 | H14: 1 | I14: საცხოვრებელი სახლები (172 ერთეული) | J14: 16550 | K14: 1200 | L14: $ 19,860,000
A15: ერთეული | B15: ცალი | C15: 50 | H15: 2 | I15: აპარტ-სასტუმრო (100 ერთეული) | J15: 3375 | K15: 1100 | L15: $ 3,712,500
A16: Eco Cabin (Loft) | C16: 6 | D16: $ 360 | E16: $ 2,000 | G16: $ 720,000 | H16: 3 | I16: კომერციული შენობები (დასასვენებელი, სპა) | J16: 3000 | K16: 800 | L16: $ 2,400,000
I17: 3. ინფრასტრუქტურა
A18: Eco Cottage | C18: 29 | D18: $ 2,610 | E18: $ 2,000 | G18: $ 5,220,000 | H18: 1 | I18: გზები, ელექტროენერგია, წყალი, ლანდშაფტი | J18: 150000 | K18: 5 | L18: $ 750,000
A19: Comfort | C19: 9 | D19: $ 1,080 | E19: $ 2,000 | G19: $ 2,160,000 | H19: 2 | I19: 4. გაუთვალისწინებელი (გაუთვალისწინებელი) | K19: 0.05 | L19: $ 1,336,125
A20: Comfort+ (60+60) | G20: $ - | H20: 3 | I20: პროექტის საერთო ღირებულება | L20: $ 28,058,625
A21: LUX Grand Villa | C21: 6 | D21: $ 1,200 | E21: $ 2,000 | G21: $ 2,400,000
D22: $ 5,250 | G22: $ 12,365,536
H23: 1 | I23: ფაზა 2: გაყიდვები და მოგებაზე გასვლა
H24: 2 | I24: გაყიდვების მთლიანი შემოსავალი (აპარტამენტები + რეზიდენციები) | K24: $ 48,150,414
A25: მესამე ზოლი | B25: მ2 | C25: 22187.6 | E25: $ 70 | G25: $ 1,553,132 | H25: 3 | I25: მინუს: მარკეტინგის და გაყიდვების ხარჯები (10%) | K25: $ 4,815,041
A26: ერთეული | B26: ცალი | C26: 48 | H26: 4 | I26: მინუს: კაპიტალური ხარჯები სუფთამოგება | K26: 9,276,748
A27: Eco Cabin (Loft) | C27: 9 | D27: $ 540 | E27: $ 1,900 | G27: $ 1,026,000 | H27: 6 | I27: საკუთრებაში აქტივების ღირებულება (კომერციული) | K27: $ 6,000,000
A28: Eco Cottage | C28: 27 | D28: $ 2,430 | E28: $ 1,900 | G28: $ 4,617,000
A29: Comfort | C29: 9 | D29: $ 1,080 | E29: $ 1,900 | G29: $ 2,052,000
A30: Comfort+ (60+60) | C30: 1 | D30: $ 120 | E30: $ 1,900 | G30: $ 228,000
A31: LUX Grand Villa | C31: 2 | D31: $ 400 | E31: $ 1,900 | G31: $ 760,000
D32: $ 4,570 | G32: $ 10,236,132
A35: მეოთხე ზოლი | B35: მ2 | C35: 11329.6 | E35: $ 60 | G35: $ 679,776
A36: ერთეული | B36: ცალი | C36: 25
A37: Eco Cabin (Loft) | C37: 14 | D37: $ 840 | E37: $ 1,900 | G37: $ 1,596,000
A38: Eco Cottage | C38: 4 | D38: $ 360 | E38: $ 1,900 | G38: $ 684,000
A39: Comfort | C39: 5 | D39: $ 600 | E39: $ 1,900 | G39: $ 1,140,000
A40: Comfort+ (60+60) | C40: 0 | G40: $ -
A41: LUX Grand Villa | C41: 2 | D41: $ 400 | E41: $ 1,900 | G41: $ 760,000
D42: $ 2,200 | G42: $ 4,859,776

Sheet Лист8
